2025-03-11 07:16:45,625	INFO worker.py:1841 -- Started a local Ray instance.
Traceback (most recent call last):
  File "/ocean/projects/cis240049p/mliu13/.conda/envs/gnn-mapf-dev2/lib/python3.10/runpy.py", line 196, in _run_module_as_main
    return _run_code(code, main_globals, None,
  File "/ocean/projects/cis240049p/mliu13/.conda/envs/gnn-mapf-dev2/lib/python3.10/runpy.py", line 86, in _run_code
    exec(code, run_globals)
  File "/jet/home/mliu13/gnn-mapf/data_collection/eecbs_batchrunner5.py", line 611, in <module>
    generic_batch_runner(args)
  File "/jet/home/mliu13/gnn-mapf/data_collection/eecbs_batchrunner5.py", line 516, in generic_batch_runner
    children = ray.get(finished_task)
  File "/ocean/projects/cis240049p/mliu13/.conda/envs/gnn-mapf-dev2/lib/python3.10/site-packages/ray/_private/auto_init_hook.py", line 21, in auto_init_wrapper
    return fn(*args, **kwargs)
  File "/ocean/projects/cis240049p/mliu13/.conda/envs/gnn-mapf-dev2/lib/python3.10/site-packages/ray/_private/client_mode_hook.py", line 103, in wrapper
    return func(*args, **kwargs)
  File "/ocean/projects/cis240049p/mliu13/.conda/envs/gnn-mapf-dev2/lib/python3.10/site-packages/ray/_private/worker.py", line 2772, in get
    values, debugger_breakpoint = worker.get_objects(object_refs, timeout=timeout)
  File "/ocean/projects/cis240049p/mliu13/.conda/envs/gnn-mapf-dev2/lib/python3.10/site-packages/ray/_private/worker.py", line 919, in get_objects
    raise value.as_instanceof_cause()
ray.exceptions.RayTaskError(CalledProcessError): [36mray::runSingleInstanceMT()[39m (pid=27767, ip=10.8.10.219)
  File "/jet/home/mliu13/gnn-mapf/data_collection/eecbs_batchrunner5.py", line 198, in runSingleInstanceMT
    helperRun(command)
  File "/jet/home/mliu13/gnn-mapf/data_collection/eecbs_batchrunner5.py", line 288, in helperRun
    subprocess.run(command, check=True, shell=True,
  File "/ocean/projects/cis240049p/mliu13/.conda/envs/gnn-mapf-dev2/lib/python3.10/subprocess.py", line 526, in run
    raise CalledProcessError(retcode, process.args,
subprocess.CalledProcessError: Command './data_collection/eecbs/build_release4/eecbs --suboptimality=2 --cutoffTime=5 --agentNum=50 --agents=/ocean/projects/cis240049p/mliu13/data/mini_benchmark_data/scens/warehouse_10_20_10_2_2-random-1.scen --outputPaths=/ocean/projects/cis240049p/mliu13/data/logs/EXP_mini/iter0/eecbs_outputs/warehouse_10_20_10_2_2/paths/warehouse_10_20_10_2_2-random-1.50.txt --bd_file=/ocean/projects/cis240049p/mliu13/data/logs/EXP_mini/iter0/eecbs_outputs/warehouse_10_20_10_2_2/bd/warehouse_10_20_10_2_2-random-1.50.txt --output=/ocean/projects/cis240049p/mliu13/data/logs/EXP_mini/iter0/eecbs_outputs/warehouse_10_20_10_2_2/csvs/worker_5d0d4bf3a5bae27e43a6c9c0dc09d5b89c51a82d02319b2a29ac29fc.csv --map=/ocean/projects/cis240049p/mliu13/data/mini_benchmark_data/maps/warehouse_10_20_10_2_2.map --sipp=1' returned non-zero exit status 127.
Map: random_32_32_10 requires 2 runs
Map: warehouse_10_20_10_2_2 requires 4 runs
2025-03-11 07:16:52,698	INFO worker.py:1841 -- Started a local Ray instance.
Traceback (most recent call last):
  File "/ocean/projects/cis240049p/mliu13/.conda/envs/gnn-mapf-dev2/lib/python3.10/runpy.py", line 196, in _run_module_as_main
    return _run_code(code, main_globals, None,
  File "/ocean/projects/cis240049p/mliu13/.conda/envs/gnn-mapf-dev2/lib/python3.10/runpy.py", line 86, in _run_code
    exec(code, run_globals)
  File "/jet/home/mliu13/gnn-mapf/data_collection/constants_generator.py", line 469, in <module>
    generic_batch_runner(args)
  File "/jet/home/mliu13/gnn-mapf/data_collection/constants_generator.py", line 400, in generic_batch_runner
    children = ray.get(finished_task)
  File "/ocean/projects/cis240049p/mliu13/.conda/envs/gnn-mapf-dev2/lib/python3.10/site-packages/ray/_private/auto_init_hook.py", line 21, in auto_init_wrapper
    return fn(*args, **kwargs)
  File "/ocean/projects/cis240049p/mliu13/.conda/envs/gnn-mapf-dev2/lib/python3.10/site-packages/ray/_private/client_mode_hook.py", line 103, in wrapper
    return func(*args, **kwargs)
  File "/ocean/projects/cis240049p/mliu13/.conda/envs/gnn-mapf-dev2/lib/python3.10/site-packages/ray/_private/worker.py", line 2772, in get
    values, debugger_breakpoint = worker.get_objects(object_refs, timeout=timeout)
  File "/ocean/projects/cis240049p/mliu13/.conda/envs/gnn-mapf-dev2/lib/python3.10/site-packages/ray/_private/worker.py", line 919, in get_objects
    raise value.as_instanceof_cause()
ray.exceptions.RayTaskError(CalledProcessError): [36mray::runSingleInstanceMT()[39m (pid=31136, ip=10.8.10.219)
  File "/jet/home/mliu13/gnn-mapf/data_collection/constants_generator.py", line 155, in runSingleInstanceMT
    helperRun(command)
  File "/jet/home/mliu13/gnn-mapf/data_collection/constants_generator.py", line 211, in helperRun
    subprocess.run(command, check=True, shell=True,
  File "/ocean/projects/cis240049p/mliu13/.conda/envs/gnn-mapf-dev2/lib/python3.10/subprocess.py", line 526, in run
    raise CalledProcessError(retcode, process.args,
subprocess.CalledProcessError: Command './data_collection/eecbs/build_release4/eecbs --suboptimality=2 --cutoffTime=1 --agentNum=1000 --agents=/ocean/projects/cis240049p/mliu13/data/mini_benchmark_data/scens/warehouse_10_20_10_2_2-random-1.scen --bd_file=/ocean/projects/cis240049p/mliu13/data/logs/EXP_Collect_BD//warehouse_10_20_10_2_2/bd/warehouse_10_20_10_2_2-random-1.1000.txt --output=/ocean/projects/cis240049p/mliu13/data/logs/EXP_Collect_BD//warehouse_10_20_10_2_2/csvs/worker_115e681c1f6acdd27f8ea329b993a149b1f188a36dd5d99410d1a21b.csv --map=/ocean/projects/cis240049p/mliu13/data/mini_benchmark_data/maps/warehouse_10_20_10_2_2.map --sipp=1' returned non-zero exit status 127.
Map: random_32_32_10 requires 2 runs
Map: warehouse_10_20_10_2_2 requires 4 runs
